2018-04-24 14:40:54,812 [15] FATAL Employee_Management_Services.Controllers.AdminController - Employee not added.System.AggregateException: One or more errors occurred. ---> System.Net.Http.HttpRequestException: An error occurred while sending the request. ---> System.Net.WebException: The underlying connection was closed: An unexpected error occurred on a receive. ---> System.IO.IOException: Unable to read data from the transport connection: An existing connection was forcibly closed by the remote host. ---> System.Net.Sockets.SocketException: An existing connection was forcibly closed by the remote host
   at System.Net.Sockets.Socket.EndReceive(IAsyncResult asyncResult)
   at System.Net.Sockets.NetworkStream.EndRead(IAsyncResult asyncResult)
   --- End of inner exception stack trace ---
   at System.Net.Sockets.NetworkStream.EndRead(IAsyncResult asyncResult)
   at System.Net.PooledStream.EndRead(IAsyncResult asyncResult)
   at System.Net.Connection.ReadCallback(IAsyncResult asyncResult)
   --- End of inner exception stack trace ---
   at System.Net.HttpWebRequest.EndGetResponse(IAsyncResult asyncResult)
   at System.Net.Http.HttpClientHandler.GetResponseCallback(IAsyncResult ar)
   --- End of inner exception stack trace ---
   --- End of inner exception stack trace ---
   at System.Threading.Tasks.Task.ThrowIfExceptional(Boolean includeTaskCanceledExceptions)
   at System.Threading.Tasks.Task`1.GetResultCore(Boolean waitCompletionNotification)
   at System.Threading.Tasks.Task`1.get_Result()
   at Employee_Management_Services.Controllers.AdminController.Create(Employee employee, String username) in D:\Employee_Management_Services\Employee_Management_Services\Controllers\AdminController.cs:line 197
---> (Inner Exception #0) System.Net.Http.HttpRequestException: An error occurred while sending the request. ---> System.Net.WebException: The underlying connection was closed: An unexpected error occurred on a receive. ---> System.IO.IOException: Unable to read data from the transport connection: An existing connection was forcibly closed by the remote host. ---> System.Net.Sockets.SocketException: An existing connection was forcibly closed by the remote host
   at System.Net.Sockets.Socket.EndReceive(IAsyncResult asyncResult)
   at System.Net.Sockets.NetworkStream.EndRead(IAsyncResult asyncResult)
   --- End of inner exception stack trace ---
   at System.Net.Sockets.NetworkStream.EndRead(IAsyncResult asyncResult)
   at System.Net.PooledStream.EndRead(IAsyncResult asyncResult)
   at System.Net.Connection.ReadCallback(IAsyncResult asyncResult)
   --- End of inner exception stack trace ---
   at System.Net.HttpWebRequest.EndGetResponse(IAsyncResult asyncResult)
   at System.Net.Http.HttpClientHandler.GetResponseCallback(IAsyncResult ar)
   --- End of inner exception stack trace ---<---

2018-04-24 14:42:24,726 [24] FATAL Employee_Management_Services.Controllers.AdminController - Employee not added.System.AggregateException: One or more errors occurred. ---> System.Net.Http.HttpRequestException: An error occurred while sending the request. ---> System.Net.WebException: The underlying connection was closed: An unexpected error occurred on a receive. ---> System.IO.IOException: Unable to read data from the transport connection: An existing connection was forcibly closed by the remote host. ---> System.Net.Sockets.SocketException: An existing connection was forcibly closed by the remote host
   at System.Net.Sockets.Socket.EndReceive(IAsyncResult asyncResult)
   at System.Net.Sockets.NetworkStream.EndRead(IAsyncResult asyncResult)
   --- End of inner exception stack trace ---
   at System.Net.Sockets.NetworkStream.EndRead(IAsyncResult asyncResult)
   at System.Net.PooledStream.EndRead(IAsyncResult asyncResult)
   at System.Net.Connection.ReadCallback(IAsyncResult asyncResult)
   --- End of inner exception stack trace ---
   at System.Net.HttpWebRequest.EndGetResponse(IAsyncResult asyncResult)
   at System.Net.Http.HttpClientHandler.GetResponseCallback(IAsyncResult ar)
   --- End of inner exception stack trace ---
   --- End of inner exception stack trace ---
   at System.Threading.Tasks.Task.ThrowIfExceptional(Boolean includeTaskCanceledExceptions)
   at System.Threading.Tasks.Task`1.GetResultCore(Boolean waitCompletionNotification)
   at System.Threading.Tasks.Task`1.get_Result()
   at Employee_Management_Services.Controllers.AdminController.Create(Employee employee, String username) in D:\Employee_Management_Services\Employee_Management_Services\Controllers\AdminController.cs:line 197
---> (Inner Exception #0) System.Net.Http.HttpRequestException: An error occurred while sending the request. ---> System.Net.WebException: The underlying connection was closed: An unexpected error occurred on a receive. ---> System.IO.IOException: Unable to read data from the transport connection: An existing connection was forcibly closed by the remote host. ---> System.Net.Sockets.SocketException: An existing connection was forcibly closed by the remote host
   at System.Net.Sockets.Socket.EndReceive(IAsyncResult asyncResult)
   at System.Net.Sockets.NetworkStream.EndRead(IAsyncResult asyncResult)
   --- End of inner exception stack trace ---
   at System.Net.Sockets.NetworkStream.EndRead(IAsyncResult asyncResult)
   at System.Net.PooledStream.EndRead(IAsyncResult asyncResult)
   at System.Net.Connection.ReadCallback(IAsyncResult asyncResult)
   --- End of inner exception stack trace ---
   at System.Net.HttpWebRequest.EndGetResponse(IAsyncResult asyncResult)
   at System.Net.Http.HttpClientHandler.GetResponseCallback(IAsyncResult ar)
   --- End of inner exception stack trace ---<---

2018-04-24 14:44:14,722 [20] FATAL Employee_Management_Services.Controllers.AdminController - Employee not added.System.AggregateException: One or more errors occurred. ---> System.Net.Http.HttpRequestException: An error occurred while sending the request. ---> System.Net.WebException: Unable to connect to the remote server ---> System.Net.Sockets.SocketException: No connection could be made because the target machine actively refused it 127.0.0.1:58410
   at System.Net.Sockets.Socket.EndConnect(IAsyncResult asyncResult)
   at System.Net.ServicePoint.ConnectSocketInternal(Boolean connectFailure, Socket s4, Socket s6, Socket& socket, IPAddress& address, ConnectSocketState state, IAsyncResult asyncResult, Exception& exception)
   --- End of inner exception stack trace ---
   at System.Net.HttpWebRequest.EndGetRequestStream(IAsyncResult asyncResult, TransportContext& context)
   at System.Net.Http.HttpClientHandler.GetRequestStreamCallback(IAsyncResult ar)
   --- End of inner exception stack trace ---
   --- End of inner exception stack trace ---
   at System.Threading.Tasks.Task.ThrowIfExceptional(Boolean includeTaskCanceledExceptions)
   at System.Threading.Tasks.Task`1.GetResultCore(Boolean waitCompletionNotification)
   at System.Threading.Tasks.Task`1.get_Result()
   at Employee_Management_Services.Controllers.AdminController.Create(Employee employee, String username) in D:\Employee_Management_Services\Employee_Management_Services\Controllers\AdminController.cs:line 197
---> (Inner Exception #0) System.Net.Http.HttpRequestException: An error occurred while sending the request. ---> System.Net.WebException: Unable to connect to the remote server ---> System.Net.Sockets.SocketException: No connection could be made because the target machine actively refused it 127.0.0.1:58410
   at System.Net.Sockets.Socket.EndConnect(IAsyncResult asyncResult)
   at System.Net.ServicePoint.ConnectSocketInternal(Boolean connectFailure, Socket s4, Socket s6, Socket& socket, IPAddress& address, ConnectSocketState state, IAsyncResult asyncResult, Exception& exception)
   --- End of inner exception stack trace ---
   at System.Net.HttpWebRequest.EndGetRequestStream(IAsyncResult asyncResult, TransportContext& context)
   at System.Net.Http.HttpClientHandler.GetRequestStreamCallback(IAsyncResult ar)
   --- End of inner exception stack trace ---<---

2018-04-24 14:56:10,955 [21] FATAL Employee_Management_Services.Controllers.HomeController - Login FailedSystem.AggregateException: One or more errors occurred. ---> System.Threading.Tasks.TaskCanceledException: A task was canceled.
   --- End of inner exception stack trace ---
   at System.Threading.Tasks.Task.ThrowIfExceptional(Boolean includeTaskCanceledExceptions)
   at System.Threading.Tasks.Task`1.GetResultCore(Boolean waitCompletionNotification)
   at System.Threading.Tasks.Task`1.get_Result()
   at Employee_Management_Services.Controllers.HomeController.Login(Employee employee) in D:\Employee_Management_Services\Employee_Management_Services\Controllers\HomeController.cs:line 100
---> (Inner Exception #0) System.Threading.Tasks.TaskCanceledException: A task was canceled.<---

2018-04-24 14:57:02,016 [7] FATAL Employee_Management_Services.Controllers.HomeController - Login FailedSystem.AggregateException: One or more errors occurred. ---> System.Net.Http.HttpRequestException: An error occurred while sending the request. ---> System.Net.WebException: The underlying connection was closed: An unexpected error occurred on a receive. ---> System.IO.IOException: Unable to read data from the transport connection: An existing connection was forcibly closed by the remote host. ---> System.Net.Sockets.SocketException: An existing connection was forcibly closed by the remote host
   at System.Net.Sockets.Socket.EndReceive(IAsyncResult asyncResult)
   at System.Net.Sockets.NetworkStream.EndRead(IAsyncResult asyncResult)
   --- End of inner exception stack trace ---
   at System.Net.Sockets.NetworkStream.EndRead(IAsyncResult asyncResult)
   at System.Net.PooledStream.EndRead(IAsyncResult asyncResult)
   at System.Net.Connection.ReadCallback(IAsyncResult asyncResult)
   --- End of inner exception stack trace ---
   at System.Net.HttpWebRequest.EndGetResponse(IAsyncResult asyncResult)
   at System.Net.Http.HttpClientHandler.GetResponseCallback(IAsyncResult ar)
   --- End of inner exception stack trace ---
   --- End of inner exception stack trace ---
   at System.Threading.Tasks.Task.ThrowIfExceptional(Boolean includeTaskCanceledExceptions)
   at System.Threading.Tasks.Task`1.GetResultCore(Boolean waitCompletionNotification)
   at System.Threading.Tasks.Task`1.get_Result()
   at Employee_Management_Services.Controllers.HomeController.Login(Employee employee) in D:\Employee_Management_Services\Employee_Management_Services\Controllers\HomeController.cs:line 100
---> (Inner Exception #0) System.Net.Http.HttpRequestException: An error occurred while sending the request. ---> System.Net.WebException: The underlying connection was closed: An unexpected error occurred on a receive. ---> System.IO.IOException: Unable to read data from the transport connection: An existing connection was forcibly closed by the remote host. ---> System.Net.Sockets.SocketException: An existing connection was forcibly closed by the remote host
   at System.Net.Sockets.Socket.EndReceive(IAsyncResult asyncResult)
   at System.Net.Sockets.NetworkStream.EndRead(IAsyncResult asyncResult)
   --- End of inner exception stack trace ---
   at System.Net.Sockets.NetworkStream.EndRead(IAsyncResult asyncResult)
   at System.Net.PooledStream.EndRead(IAsyncResult asyncResult)
   at System.Net.Connection.ReadCallback(IAsyncResult asyncResult)
   --- End of inner exception stack trace ---
   at System.Net.HttpWebRequest.EndGetResponse(IAsyncResult asyncResult)
   at System.Net.Http.HttpClientHandler.GetResponseCallback(IAsyncResult ar)
   --- End of inner exception stack trace ---<---

2018-04-24 18:22:21,114 [15] FATAL Employee_Management_Services.Controllers.AdminController - System.AggregateException: One or more errors occurred. ---> System.Net.Http.HttpRequestException: An error occurred while sending the request. ---> System.Net.WebException: The underlying connection was closed: An unexpected error occurred on a receive. ---> System.IO.IOException: Unable to read data from the transport connection: An existing connection was forcibly closed by the remote host. ---> System.Net.Sockets.SocketException: An existing connection was forcibly closed by the remote host
   at System.Net.Sockets.Socket.EndReceive(IAsyncResult asyncResult)
   at System.Net.Sockets.NetworkStream.EndRead(IAsyncResult asyncResult)
   --- End of inner exception stack trace ---
   at System.Net.Sockets.NetworkStream.EndRead(IAsyncResult asyncResult)
   at System.Net.PooledStream.EndRead(IAsyncResult asyncResult)
   at System.Net.Connection.ReadCallback(IAsyncResult asyncResult)
   --- End of inner exception stack trace ---
   at System.Net.HttpWebRequest.EndGetResponse(IAsyncResult asyncResult)
   at System.Net.Http.HttpClientHandler.GetResponseCallback(IAsyncResult ar)
   --- End of inner exception stack trace ---
   --- End of inner exception stack trace ---
   at System.Threading.Tasks.Task.ThrowIfExceptional(Boolean includeTaskCanceledExceptions)
   at System.Threading.Tasks.Task`1.GetResultCore(Boolean waitCompletionNotification)
   at System.Threading.Tasks.Task`1.get_Result()
   at Employee_Management_Services.Controllers.AdminController.Login(Admin admin) in D:\Employee_Management_Services\Employee_Management_Services\Controllers\AdminController.cs:line 400
---> (Inner Exception #0) System.Net.Http.HttpRequestException: An error occurred while sending the request. ---> System.Net.WebException: The underlying connection was closed: An unexpected error occurred on a receive. ---> System.IO.IOException: Unable to read data from the transport connection: An existing connection was forcibly closed by the remote host. ---> System.Net.Sockets.SocketException: An existing connection was forcibly closed by the remote host
   at System.Net.Sockets.Socket.EndReceive(IAsyncResult asyncResult)
   at System.Net.Sockets.NetworkStream.EndRead(IAsyncResult asyncResult)
   --- End of inner exception stack trace ---
   at System.Net.Sockets.NetworkStream.EndRead(IAsyncResult asyncResult)
   at System.Net.PooledStream.EndRead(IAsyncResult asyncResult)
   at System.Net.Connection.ReadCallback(IAsyncResult asyncResult)
   --- End of inner exception stack trace ---
   at System.Net.HttpWebRequest.EndGetResponse(IAsyncResult asyncResult)
   at System.Net.Http.HttpClientHandler.GetResponseCallback(IAsyncResult ar)
   --- End of inner exception stack trace ---<---

2018-04-25 10:51:01,635 [11] FATAL Employee_Management_Services.Controllers.AdminController - System.AggregateException: One or more errors occurred. ---> System.Threading.Tasks.TaskCanceledException: A task was canceled.
   --- End of inner exception stack trace ---
   at System.Threading.Tasks.Task.ThrowIfExceptional(Boolean includeTaskCanceledExceptions)
   at System.Threading.Tasks.Task`1.GetResultCore(Boolean waitCompletionNotification)
   at System.Threading.Tasks.Task`1.get_Result()
   at Employee_Management_Services.Controllers.AdminController.Index(String userName, String sortOrder, String currentFilter, String searchString, Nullable`1 page, String departmentFilter, String genderFilter) in D:\Employee_Management_Services\Employee_Management_Services\Controllers\AdminController.cs:line 596
---> (Inner Exception #0) System.Threading.Tasks.TaskCanceledException: A task was canceled.<---

2018-04-25 11:33:24,186 [10] FATAL Employee_Management_Services.Controllers.EmployeeController - System.AggregateException: One or more errors occurred. ---> System.Threading.Tasks.TaskCanceledException: A task was canceled.
   --- End of inner exception stack trace ---
   at System.Threading.Tasks.Task.ThrowIfExceptional(Boolean includeTaskCanceledExceptions)
   at System.Threading.Tasks.Task`1.GetResultCore(Boolean waitCompletionNotification)
   at System.Threading.Tasks.Task`1.get_Result()
   at Employee_Management_Services.Controllers.EmployeeController.Index(String id, String organisationID, String sortOrder, String currentFilter, String searchString, Nullable`1 page, String departmentFilter, String genderFilter) in D:\Employee_Management_Services\Employee_Management_Services\Controllers\EmployeeController.cs:line 163
---> (Inner Exception #0) System.Threading.Tasks.TaskCanceledException: A task was canceled.<---

2018-04-25 16:53:18,399 [8] FATAL Employee_Management_Services.Controllers.AdminController - Employee not added.System.AggregateException: One or more errors occurred. ---> System.Threading.Tasks.TaskCanceledException: A task was canceled.
   --- End of inner exception stack trace ---
   at System.Threading.Tasks.Task.ThrowIfExceptional(Boolean includeTaskCanceledExceptions)
   at System.Threading.Tasks.Task`1.GetResultCore(Boolean waitCompletionNotification)
   at System.Threading.Tasks.Task`1.get_Result()
   at Employee_Management_Services.Controllers.AdminController.Create(Employee employee, String username) in D:\Employee_Management_Services\Employee_Management_Services\Controllers\AdminController.cs:line 197
---> (Inner Exception #0) System.Threading.Tasks.TaskCanceledException: A task was canceled.<---

2018-04-26 10:31:53,771 [421] FATAL Employee_Management_Services.Controllers.AdminController - System.AggregateException: One or more errors occurred. ---> System.Net.Http.HttpRequestException: An error occurred while sending the request. ---> System.Net.WebException: Unable to connect to the remote server ---> System.Net.Sockets.SocketException: No connection could be made because the target machine actively refused it 127.0.0.1:58410
   at System.Net.Sockets.Socket.EndConnect(IAsyncResult asyncResult)
   at System.Net.ServicePoint.ConnectSocketInternal(Boolean connectFailure, Socket s4, Socket s6, Socket& socket, IPAddress& address, ConnectSocketState state, IAsyncResult asyncResult, Exception& exception)
   --- End of inner exception stack trace ---
   at System.Net.HttpWebRequest.EndGetRequestStream(IAsyncResult asyncResult, TransportContext& context)
   at System.Net.Http.HttpClientHandler.GetRequestStreamCallback(IAsyncResult ar)
   --- End of inner exception stack trace ---
   --- End of inner exception stack trace ---
   at System.Threading.Tasks.Task.ThrowIfExceptional(Boolean includeTaskCanceledExceptions)
   at System.Threading.Tasks.Task`1.GetResultCore(Boolean waitCompletionNotification)
   at System.Threading.Tasks.Task`1.get_Result()
   at Employee_Management_Services.Controllers.AdminController.Login(Admin admin) in D:\Employee_Management_Services\Employee_Management_Services\Controllers\AdminController.cs:line 400
---> (Inner Exception #0) System.Net.Http.HttpRequestException: An error occurred while sending the request. ---> System.Net.WebException: Unable to connect to the remote server ---> System.Net.Sockets.SocketException: No connection could be made because the target machine actively refused it 127.0.0.1:58410
   at System.Net.Sockets.Socket.EndConnect(IAsyncResult asyncResult)
   at System.Net.ServicePoint.ConnectSocketInternal(Boolean connectFailure, Socket s4, Socket s6, Socket& socket, IPAddress& address, ConnectSocketState state, IAsyncResult asyncResult, Exception& exception)
   --- End of inner exception stack trace ---
   at System.Net.HttpWebRequest.EndGetRequestStream(IAsyncResult asyncResult, TransportContext& context)
   at System.Net.Http.HttpClientHandler.GetRequestStreamCallback(IAsyncResult ar)
   --- End of inner exception stack trace ---<---

2018-04-26 11:44:04,962 [8] FATAL Employee_Management_Services.Controllers.EmployeeController - System.AggregateException: One or more errors occurred. ---> System.Net.Http.HttpRequestException: An error occurred while sending the request. ---> System.Net.WebException: The underlying connection was closed: An unexpected error occurred on a receive. ---> System.IO.IOException: Unable to read data from the transport connection: An existing connection was forcibly closed by the remote host. ---> System.Net.Sockets.SocketException: An existing connection was forcibly closed by the remote host
   at System.Net.Sockets.Socket.EndReceive(IAsyncResult asyncResult)
   at System.Net.Sockets.NetworkStream.EndRead(IAsyncResult asyncResult)
   --- End of inner exception stack trace ---
   at System.Net.Sockets.NetworkStream.EndRead(IAsyncResult asyncResult)
   at System.Net.PooledStream.EndRead(IAsyncResult asyncResult)
   at System.Net.Connection.ReadCallback(IAsyncResult asyncResult)
   --- End of inner exception stack trace ---
   at System.Net.HttpWebRequest.EndGetResponse(IAsyncResult asyncResult)
   at System.Net.Http.HttpClientHandler.GetResponseCallback(IAsyncResult ar)
   --- End of inner exception stack trace ---
   --- End of inner exception stack trace ---
   at System.Threading.Tasks.Task.ThrowIfExceptional(Boolean includeTaskCanceledExceptions)
   at System.Threading.Tasks.Task`1.GetResultCore(Boolean waitCompletionNotification)
   at System.Threading.Tasks.Task`1.get_Result()
   at Employee_Management_Services.Controllers.EmployeeController.Index(String id, String organisationID, String sortOrder, String currentFilter, String searchString, Nullable`1 page, String departmentFilter, String genderFilter) in D:\Employee_Management_Services\Employee_Management_Services\Controllers\EmployeeController.cs:line 163
---> (Inner Exception #0) System.Net.Http.HttpRequestException: An error occurred while sending the request. ---> System.Net.WebException: The underlying connection was closed: An unexpected error occurred on a receive. ---> System.IO.IOException: Unable to read data from the transport connection: An existing connection was forcibly closed by the remote host. ---> System.Net.Sockets.SocketException: An existing connection was forcibly closed by the remote host
   at System.Net.Sockets.Socket.EndReceive(IAsyncResult asyncResult)
   at System.Net.Sockets.NetworkStream.EndRead(IAsyncResult asyncResult)
   --- End of inner exception stack trace ---
   at System.Net.Sockets.NetworkStream.EndRead(IAsyncResult asyncResult)
   at System.Net.PooledStream.EndRead(IAsyncResult asyncResult)
   at System.Net.Connection.ReadCallback(IAsyncResult asyncResult)
   --- End of inner exception stack trace ---
   at System.Net.HttpWebRequest.EndGetResponse(IAsyncResult asyncResult)
   at System.Net.Http.HttpClientHandler.GetResponseCallback(IAsyncResult ar)
   --- End of inner exception stack trace ---<---

2018-04-26 18:15:47,498 [6] FATAL Employee_Management_Services.Controllers.AdminController - System.AggregateException: One or more errors occurred. ---> System.Net.Http.HttpRequestException: An error occurred while sending the request. ---> System.Net.WebException: Unable to connect to the remote server ---> System.Net.Sockets.SocketException: No connection could be made because the target machine actively refused it 127.0.0.1:58410
   at System.Net.Sockets.Socket.EndConnect(IAsyncResult asyncResult)
   at System.Net.ServicePoint.ConnectSocketInternal(Boolean connectFailure, Socket s4, Socket s6, Socket& socket, IPAddress& address, ConnectSocketState state, IAsyncResult asyncResult, Exception& exception)
   --- End of inner exception stack trace ---
   at System.Net.HttpWebRequest.EndGetResponse(IAsyncResult asyncResult)
   at System.Net.Http.HttpClientHandler.GetResponseCallback(IAsyncResult ar)
   --- End of inner exception stack trace ---
   --- End of inner exception stack trace ---
   at System.Threading.Tasks.Task.ThrowIfExceptional(Boolean includeTaskCanceledExceptions)
   at System.Threading.Tasks.Task.Wait(Int32 millisecondsTimeout, CancellationToken cancellationToken)
   at System.Threading.Tasks.Task.Wait()
   at Employee_Management_Services.Controllers.AdminController.UserAccountInfo(String id, String organisationID) in D:\Employee_Management_Services\Employee_Management_Services\Controllers\AdminController.cs:line 511
---> (Inner Exception #0) System.Net.Http.HttpRequestException: An error occurred while sending the request. ---> System.Net.WebException: Unable to connect to the remote server ---> System.Net.Sockets.SocketException: No connection could be made because the target machine actively refused it 127.0.0.1:58410
   at System.Net.Sockets.Socket.EndConnect(IAsyncResult asyncResult)
   at System.Net.ServicePoint.ConnectSocketInternal(Boolean connectFailure, Socket s4, Socket s6, Socket& socket, IPAddress& address, ConnectSocketState state, IAsyncResult asyncResult, Exception& exception)
   --- End of inner exception stack trace ---
   at System.Net.HttpWebRequest.EndGetResponse(IAsyncResult asyncResult)
   at System.Net.Http.HttpClientHandler.GetResponseCallback(IAsyncResult ar)
   --- End of inner exception stack trace ---<---

2018-04-26 19:01:53,022 [5] FATAL Employee_Management_Services.Controllers.AdminController - System.NullReferenceException: Object reference not set to an instance of an object.
   at Employee_Management_Services.Controllers.AdminController.Edit(Int32 id, Employee employee, String organisationID) in D:\Employee_Management_Services\Employee_Management_Services\Controllers\AdminController.cs:line 283
2018-04-26 19:02:48,309 [5] FATAL Employee_Management_Services.Controllers.AdminController - System.NullReferenceException: Object reference not set to an instance of an object.
   at Employee_Management_Services.Controllers.AdminController.Edit(Int32 id, Employee employee, String organisationID) in D:\Employee_Management_Services\Employee_Management_Services\Controllers\AdminController.cs:line 283
2018-04-27 11:24:00,107 [8] FATAL Employee_Management_Services.Controllers.AdminController - Employee not added.System.AggregateException: One or more errors occurred. ---> System.Net.Http.HttpRequestException: An error occurred while sending the request. ---> System.Net.WebException: The underlying connection was closed: An unexpected error occurred on a receive. ---> System.IO.IOException: Unable to read data from the transport connection: An existing connection was forcibly closed by the remote host. ---> System.Net.Sockets.SocketException: An existing connection was forcibly closed by the remote host
   at System.Net.Sockets.Socket.EndReceive(IAsyncResult asyncResult)
   at System.Net.Sockets.NetworkStream.EndRead(IAsyncResult asyncResult)
   --- End of inner exception stack trace ---
   at System.Net.Sockets.NetworkStream.EndRead(IAsyncResult asyncResult)
   at System.Net.PooledStream.EndRead(IAsyncResult asyncResult)
   at System.Net.Connection.ReadCallback(IAsyncResult asyncResult)
   --- End of inner exception stack trace ---
   at System.Net.HttpWebRequest.EndGetResponse(IAsyncResult asyncResult)
   at System.Net.Http.HttpClientHandler.GetResponseCallback(IAsyncResult ar)
   --- End of inner exception stack trace ---
   --- End of inner exception stack trace ---
   at System.Threading.Tasks.Task.ThrowIfExceptional(Boolean includeTaskCanceledExceptions)
   at System.Threading.Tasks.Task`1.GetResultCore(Boolean waitCompletionNotification)
   at System.Threading.Tasks.Task`1.get_Result()
   at Employee_Management_Services.Controllers.AdminController.Create(Employee employee, String username) in D:\Employee_Management_Services\Employee_Management_Services\Controllers\AdminController.cs:line 199
---> (Inner Exception #0) System.Net.Http.HttpRequestException: An error occurred while sending the request. ---> System.Net.WebException: The underlying connection was closed: An unexpected error occurred on a receive. ---> System.IO.IOException: Unable to read data from the transport connection: An existing connection was forcibly closed by the remote host. ---> System.Net.Sockets.SocketException: An existing connection was forcibly closed by the remote host
   at System.Net.Sockets.Socket.EndReceive(IAsyncResult asyncResult)
   at System.Net.Sockets.NetworkStream.EndRead(IAsyncResult asyncResult)
   --- End of inner exception stack trace ---
   at System.Net.Sockets.NetworkStream.EndRead(IAsyncResult asyncResult)
   at System.Net.PooledStream.EndRead(IAsyncResult asyncResult)
   at System.Net.Connection.ReadCallback(IAsyncResult asyncResult)
   --- End of inner exception stack trace ---
   at System.Net.HttpWebRequest.EndGetResponse(IAsyncResult asyncResult)
   at System.Net.Http.HttpClientHandler.GetResponseCallback(IAsyncResult ar)
   --- End of inner exception stack trace ---<---

2018-04-28 19:11:14,223 [8] FATAL Employee_Management_Services.Controllers.EmployeeController - System.NullReferenceException: Object reference not set to an instance of an object.
   at Employee_Management_Services.Controllers.EmployeeController.ChangePassword(Int32 id, String organisationID) in D:\Employee_Management_Services\Employee_Management_Services\Controllers\EmployeeController.cs:line 284
2018-04-28 19:11:17,992 [10] FATAL Employee_Management_Services.Controllers.EmployeeController - System.NullReferenceException: Object reference not set to an instance of an object.
   at Employee_Management_Services.Controllers.EmployeeController.ChangePassword(Int32 id, String organisationID) in D:\Employee_Management_Services\Employee_Management_Services\Controllers\EmployeeController.cs:line 284
2018-04-30 22:22:17,897 [8] FATAL Employee_Management_Services.Controllers.AdminController - System.AggregateException: One or more errors occurred. ---> System.Threading.Tasks.TaskCanceledException: A task was canceled.
   --- End of inner exception stack trace ---
   at System.Threading.Tasks.Task.ThrowIfExceptional(Boolean includeTaskCanceledExceptions)
   at System.Threading.Tasks.Task`1.GetResultCore(Boolean waitCompletionNotification)
   at System.Threading.Tasks.Task`1.get_Result()
   at Employee_Management_Services.Controllers.AdminController.Index(String userName, String organisationID, String sortOrder, String currentFilter, String searchString, Nullable`1 page, String departmentFilter, String genderFilter) in D:\Employee_Management_Services\Employee_Management_Services\Controllers\AdminController.cs:line 667
---> (Inner Exception #0) System.Threading.Tasks.TaskCanceledException: A task was canceled.<---

2018-05-02 22:19:23,062 [8] FATAL Employee_Management_Services.Controllers.AdminController - System.AggregateException: One or more errors occurred. ---> System.Threading.Tasks.TaskCanceledException: A task was canceled.
   --- End of inner exception stack trace ---
   at System.Threading.Tasks.Task.ThrowIfExceptional(Boolean includeTaskCanceledExceptions)
   at System.Threading.Tasks.Task`1.GetResultCore(Boolean waitCompletionNotification)
   at System.Threading.Tasks.Task`1.get_Result()
   at Employee_Management_Services.Controllers.AdminController.ChangeStatus(Int32 id, Employee employee, String organisationID) in D:\Employee_Management_Services\Employee_Management_Services\Controllers\AdminController.cs:line 359
---> (Inner Exception #0) System.Threading.Tasks.TaskCanceledException: A task was canceled.<---

2018-05-02 22:25:34,043 [21] FATAL Employee_Management_Services.Controllers.AdminController - System.AggregateException: One or more errors occurred. ---> System.Threading.Tasks.TaskCanceledException: A task was canceled.
   --- End of inner exception stack trace ---
   at System.Threading.Tasks.Task.ThrowIfExceptional(Boolean includeTaskCanceledExceptions)
   at System.Threading.Tasks.Task`1.GetResultCore(Boolean waitCompletionNotification)
   at System.Threading.Tasks.Task`1.get_Result()
   at Employee_Management_Services.Controllers.AdminController.ChangeStatus(Int32 id, Employee employee, String organisationID) in D:\Employee_Management_Services\Employee_Management_Services\Controllers\AdminController.cs:line 359
---> (Inner Exception #0) System.Threading.Tasks.TaskCanceledException: A task was canceled.<---

2018-05-02 22:29:39,147 [12] FATAL Employee_Management_Services.Controllers.AdminController - System.AggregateException: One or more errors occurred. ---> System.Threading.Tasks.TaskCanceledException: A task was canceled.
   --- End of inner exception stack trace ---
   at System.Threading.Tasks.Task.ThrowIfExceptional(Boolean includeTaskCanceledExceptions)
   at System.Threading.Tasks.Task`1.GetResultCore(Boolean waitCompletionNotification)
   at System.Threading.Tasks.Task`1.get_Result()
   at Employee_Management_Services.Controllers.AdminController.ChangeStatus(Int32 id, Employee employee, String organisationID) in D:\Employee_Management_Services\Employee_Management_Services\Controllers\AdminController.cs:line 359
---> (Inner Exception #0) System.Threading.Tasks.TaskCanceledException: A task was canceled.<---

2018-05-03 02:39:09,218 [19] FATAL Employee_Management_Services.Controllers.EmployeeController - System.AggregateException: One or more errors occurred. ---> System.Net.Http.HttpRequestException: An error occurred while sending the request. ---> System.Net.WebException: Unable to connect to the remote server ---> System.Net.Sockets.SocketException: No connection could be made because the target machine actively refused it 127.0.0.1:58410
   at System.Net.Sockets.Socket.EndConnect(IAsyncResult asyncResult)
   at System.Net.ServicePoint.ConnectSocketInternal(Boolean connectFailure, Socket s4, Socket s6, Socket& socket, IPAddress& address, ConnectSocketState state, IAsyncResult asyncResult, Exception& exception)
   --- End of inner exception stack trace ---
   at System.Net.HttpWebRequest.EndGetResponse(IAsyncResult asyncResult)
   at System.Net.Http.HttpClientHandler.GetResponseCallback(IAsyncResult ar)
   --- End of inner exception stack trace ---
   --- End of inner exception stack trace ---
   at System.Threading.Tasks.Task.ThrowIfExceptional(Boolean includeTaskCanceledExceptions)
   at System.Threading.Tasks.Task.Wait(Int32 millisecondsTimeout, CancellationToken cancellationToken)
   at System.Threading.Tasks.Task.Wait()
   at Employee_Management_Services.Controllers.EmployeeController.Details(Int32 id, String userdetail, String organisationID) in D:\Employee_Management_Services\Employee_Management_Services\Controllers\EmployeeController.cs:line 49
---> (Inner Exception #0) System.Net.Http.HttpRequestException: An error occurred while sending the request. ---> System.Net.WebException: Unable to connect to the remote server ---> System.Net.Sockets.SocketException: No connection could be made because the target machine actively refused it 127.0.0.1:58410
   at System.Net.Sockets.Socket.EndConnect(IAsyncResult asyncResult)
   at System.Net.ServicePoint.ConnectSocketInternal(Boolean connectFailure, Socket s4, Socket s6, Socket& socket, IPAddress& address, ConnectSocketState state, IAsyncResult asyncResult, Exception& exception)
   --- End of inner exception stack trace ---
   at System.Net.HttpWebRequest.EndGetResponse(IAsyncResult asyncResult)
   at System.Net.Http.HttpClientHandler.GetResponseCallback(IAsyncResult ar)
   --- End of inner exception stack trace ---<---

2018-05-03 02:43:53,046 [35] FATAL Employee_Management_Services.Controllers.EmployeeController - System.AggregateException: One or more errors occurred. ---> System.Net.Http.HttpRequestException: An error occurred while sending the request. ---> System.Net.WebException: Unable to connect to the remote server ---> System.Net.Sockets.SocketException: No connection could be made because the target machine actively refused it 127.0.0.1:58410
   at System.Net.Sockets.Socket.EndConnect(IAsyncResult asyncResult)
   at System.Net.ServicePoint.ConnectSocketInternal(Boolean connectFailure, Socket s4, Socket s6, Socket& socket, IPAddress& address, ConnectSocketState state, IAsyncResult asyncResult, Exception& exception)
   --- End of inner exception stack trace ---
   at System.Net.HttpWebRequest.EndGetResponse(IAsyncResult asyncResult)
   at System.Net.Http.HttpClientHandler.GetResponseCallback(IAsyncResult ar)
   --- End of inner exception stack trace ---
   --- End of inner exception stack trace ---
   at System.Threading.Tasks.Task.ThrowIfExceptional(Boolean includeTaskCanceledExceptions)
   at System.Threading.Tasks.Task.Wait(Int32 millisecondsTimeout, CancellationToken cancellationToken)
   at System.Threading.Tasks.Task.Wait()
   at Employee_Management_Services.Controllers.EmployeeController.Details(Int32 id, String userdetail, String organisationID) in D:\Employee_Management_Services\Employee_Management_Services\Controllers\EmployeeController.cs:line 49
---> (Inner Exception #0) System.Net.Http.HttpRequestException: An error occurred while sending the request. ---> System.Net.WebException: Unable to connect to the remote server ---> System.Net.Sockets.SocketException: No connection could be made because the target machine actively refused it 127.0.0.1:58410
   at System.Net.Sockets.Socket.EndConnect(IAsyncResult asyncResult)
   at System.Net.ServicePoint.ConnectSocketInternal(Boolean connectFailure, Socket s4, Socket s6, Socket& socket, IPAddress& address, ConnectSocketState state, IAsyncResult asyncResult, Exception& exception)
   --- End of inner exception stack trace ---
   at System.Net.HttpWebRequest.EndGetResponse(IAsyncResult asyncResult)
   at System.Net.Http.HttpClientHandler.GetResponseCallback(IAsyncResult ar)
   --- End of inner exception stack trace ---<---

2018-05-07 15:02:12,882 [5] FATAL Employee_Management_Services.Controllers.AdminController - System.AggregateException: One or more errors occurred. ---> System.Threading.Tasks.TaskCanceledException: A task was canceled.
   --- End of inner exception stack trace ---
   at System.Threading.Tasks.Task.ThrowIfExceptional(Boolean includeTaskCanceledExceptions)
   at System.Threading.Tasks.Task.Wait(Int32 millisecondsTimeout, CancellationToken cancellationToken)
   at System.Threading.Tasks.Task.Wait()
   at Employee_Management_Services.Controllers.AdminController.Details(Int32 id, String userName, String organisationID) in D:\Employee_Management_Services\Employee_Management_Services\Controllers\AdminController.cs:line 623
---> (Inner Exception #0) System.Threading.Tasks.TaskCanceledException: A task was canceled.<---

2018-05-07 15:09:24,396 [25] FATAL Employee_Management_Services.Controllers.AdminController - System.AggregateException: One or more errors occurred. ---> System.Threading.Tasks.TaskCanceledException: A task was canceled.
   --- End of inner exception stack trace ---
   at System.Threading.Tasks.Task.ThrowIfExceptional(Boolean includeTaskCanceledExceptions)
   at System.Threading.Tasks.Task.Wait(Int32 millisecondsTimeout, CancellationToken cancellationToken)
   at System.Threading.Tasks.Task.Wait()
   at Employee_Management_Services.Controllers.AdminController.Details(Int32 id, String userName, String organisationID) in D:\Employee_Management_Services\Employee_Management_Services\Controllers\AdminController.cs:line 623
---> (Inner Exception #0) System.Threading.Tasks.TaskCanceledException: A task was canceled.<---

2018-05-07 15:11:54,016 [15] FATAL Employee_Management_Services.Controllers.AdminController - System.AggregateException: One or more errors occurred. ---> System.Threading.Tasks.TaskCanceledException: A task was canceled.
   --- End of inner exception stack trace ---
   at System.Threading.Tasks.Task.ThrowIfExceptional(Boolean includeTaskCanceledExceptions)
   at System.Threading.Tasks.Task.Wait(Int32 millisecondsTimeout, CancellationToken cancellationToken)
   at System.Threading.Tasks.Task.Wait()
   at Employee_Management_Services.Controllers.AdminController.Details(Int32 id, String userName, String organisationID) in D:\Employee_Management_Services\Employee_Management_Services\Controllers\AdminController.cs:line 623
---> (Inner Exception #0) System.Threading.Tasks.TaskCanceledException: A task was canceled.<---

2018-05-07 15:18:10,267 [26] FATAL Employee_Management_Services.Controllers.AdminController - System.AggregateException: One or more errors occurred. ---> System.Threading.Tasks.TaskCanceledException: A task was canceled.
   --- End of inner exception stack trace ---
   at System.Threading.Tasks.Task.ThrowIfExceptional(Boolean includeTaskCanceledExceptions)
   at System.Threading.Tasks.Task.Wait(Int32 millisecondsTimeout, CancellationToken cancellationToken)
   at System.Threading.Tasks.Task.Wait()
   at Employee_Management_Services.Controllers.AdminController.Details(Int32 id, String userName, String organisationID) in D:\Employee_Management_Services\Employee_Management_Services\Controllers\AdminController.cs:line 623
---> (Inner Exception #0) System.Threading.Tasks.TaskCanceledException: A task was canceled.<---

2018-05-08 11:19:33,512 [7] FATAL Employee_Management_Services.Controllers.AdminController - Employee not added.System.Net.Mail.SmtpException: The operation has timed out.
   at System.Net.Mail.SmtpClient.Send(MailMessage message)
   at Employee_Management_Services.Controllers.AdminController.SendEmailToEmployee(Employee employee) in D:\Employee_Management_Services\Employee_Management_Services\Controllers\AdminController.cs:line 178
   at Employee_Management_Services.Controllers.AdminController.Create(Employee employee, String username) in D:\Employee_Management_Services\Employee_Management_Services\Controllers\AdminController.cs:line 243
2018-05-08 11:34:09,435 [9] FATAL Employee_Management_Services.Controllers.AdminController - Employee not added.System.Net.Mail.SmtpException: Failure sending mail. ---> System.Net.WebException: Unable to connect to the remote server ---> System.Net.Sockets.SocketException: A connection attempt failed because the connected party did not properly respond after a period of time, or established connection failed because connected host has failed to respond 74.125.24.109:587
   at System.Net.Sockets.Socket.DoConnect(EndPoint endPointSnapshot, SocketAddress socketAddress)
   at System.Net.ServicePoint.ConnectSocketInternal(Boolean connectFailure, Socket s4, Socket s6, Socket& socket, IPAddress& address, ConnectSocketState state, IAsyncResult asyncResult, Exception& exception)
   --- End of inner exception stack trace ---
   at System.Net.ServicePoint.GetConnection(PooledStream PooledStream, Object owner, Boolean async, IPAddress& address, Socket& abortSocket, Socket& abortSocket6)
   at System.Net.PooledStream.Activate(Object owningObject, Boolean async, GeneralAsyncDelegate asyncCallback)
   at System.Net.PooledStream.Activate(Object owningObject, GeneralAsyncDelegate asyncCallback)
   at System.Net.ConnectionPool.GetConnection(Object owningObject, GeneralAsyncDelegate asyncCallback, Int32 creationTimeout)
   at System.Net.Mail.SmtpConnection.GetConnection(ServicePoint servicePoint)
   at System.Net.Mail.SmtpTransport.GetConnection(ServicePoint servicePoint)
   at System.Net.Mail.SmtpClient.GetConnection()
   at System.Net.Mail.SmtpClient.Send(MailMessage message)
   --- End of inner exception stack trace ---
   at System.Net.Mail.SmtpClient.Send(MailMessage message)
   at Employee_Management_Services.Controllers.AdminController.SendEmailToEmployee(Employee employee) in D:\Employee_Management_Services\Employee_Management_Services\Controllers\AdminController.cs:line 176
   at Employee_Management_Services.Controllers.AdminController.Create(Employee employee, String username) in D:\Employee_Management_Services\Employee_Management_Services\Controllers\AdminController.cs:line 241
2018-05-08 11:36:12,480 [9] FATAL Employee_Management_Services.Controllers.AdminController - Employee not added.System.Net.Mail.SmtpException: Failure sending mail. ---> System.Net.WebException: Unable to connect to the remote server ---> System.Net.Sockets.SocketException: A connection attempt failed because the connected party did not properly respond after a period of time, or established connection failed because connected host has failed to respond 74.125.24.108:587
   at System.Net.Sockets.Socket.DoConnect(EndPoint endPointSnapshot, SocketAddress socketAddress)
   at System.Net.ServicePoint.ConnectSocketInternal(Boolean connectFailure, Socket s4, Socket s6, Socket& socket, IPAddress& address, ConnectSocketState state, IAsyncResult asyncResult, Exception& exception)
   --- End of inner exception stack trace ---
   at System.Net.ServicePoint.GetConnection(PooledStream PooledStream, Object owner, Boolean async, IPAddress& address, Socket& abortSocket, Socket& abortSocket6)
   at System.Net.PooledStream.Activate(Object owningObject, Boolean async, GeneralAsyncDelegate asyncCallback)
   at System.Net.PooledStream.Activate(Object owningObject, GeneralAsyncDelegate asyncCallback)
   at System.Net.ConnectionPool.GetConnection(Object owningObject, GeneralAsyncDelegate asyncCallback, Int32 creationTimeout)
   at System.Net.Mail.SmtpConnection.GetConnection(ServicePoint servicePoint)
   at System.Net.Mail.SmtpTransport.GetConnection(ServicePoint servicePoint)
   at System.Net.Mail.SmtpClient.GetConnection()
   at System.Net.Mail.SmtpClient.Send(MailMessage message)
   --- End of inner exception stack trace ---
   at System.Net.Mail.SmtpClient.Send(MailMessage message)
   at Employee_Management_Services.Controllers.AdminController.SendEmailToEmployee(Employee employee) in D:\Employee_Management_Services\Employee_Management_Services\Controllers\AdminController.cs:line 176
   at Employee_Management_Services.Controllers.AdminController.Create(Employee employee, String username) in D:\Employee_Management_Services\Employee_Management_Services\Controllers\AdminController.cs:line 241
2018-05-08 11:38:19,220 [9] FATAL Employee_Management_Services.Controllers.AdminController - Employee not added.System.Net.Mail.SmtpException: Failure sending mail. ---> System.Net.WebException: Unable to connect to the remote server ---> System.Net.Sockets.SocketException: A connection attempt failed because the connected party did not properly respond after a period of time, or established connection failed because connected host has failed to respond 74.125.24.108:587
   at System.Net.Sockets.Socket.DoConnect(EndPoint endPointSnapshot, SocketAddress socketAddress)
   at System.Net.ServicePoint.ConnectSocketInternal(Boolean connectFailure, Socket s4, Socket s6, Socket& socket, IPAddress& address, ConnectSocketState state, IAsyncResult asyncResult, Exception& exception)
   --- End of inner exception stack trace ---
   at System.Net.ServicePoint.GetConnection(PooledStream PooledStream, Object owner, Boolean async, IPAddress& address, Socket& abortSocket, Socket& abortSocket6)
   at System.Net.PooledStream.Activate(Object owningObject, Boolean async, GeneralAsyncDelegate asyncCallback)
   at System.Net.PooledStream.Activate(Object owningObject, GeneralAsyncDelegate asyncCallback)
   at System.Net.ConnectionPool.GetConnection(Object owningObject, GeneralAsyncDelegate asyncCallback, Int32 creationTimeout)
   at System.Net.Mail.SmtpConnection.GetConnection(ServicePoint servicePoint)
   at System.Net.Mail.SmtpTransport.GetConnection(ServicePoint servicePoint)
   at System.Net.Mail.SmtpClient.GetConnection()
   at System.Net.Mail.SmtpClient.Send(MailMessage message)
   --- End of inner exception stack trace ---
   at System.Net.Mail.SmtpClient.Send(MailMessage message)
   at Employee_Management_Services.Controllers.AdminController.SendEmailToEmployee(Employee employee) in D:\Employee_Management_Services\Employee_Management_Services\Controllers\AdminController.cs:line 176
   at Employee_Management_Services.Controllers.AdminController.Create(Employee employee, String username) in D:\Employee_Management_Services\Employee_Management_Services\Controllers\AdminController.cs:line 241
2018-05-08 11:39:26,936 [9] FATAL Employee_Management_Services.Controllers.AdminController - Employee not added.System.Net.Mail.SmtpException: Failure sending mail. ---> System.Net.WebException: Unable to connect to the remote server ---> System.Net.Sockets.SocketException: A connection attempt failed because the connected party did not properly respond after a period of time, or established connection failed because connected host has failed to respond 74.125.24.108:587
   at System.Net.Sockets.Socket.DoConnect(EndPoint endPointSnapshot, SocketAddress socketAddress)
   at System.Net.ServicePoint.ConnectSocketInternal(Boolean connectFailure, Socket s4, Socket s6, Socket& socket, IPAddress& address, ConnectSocketState state, IAsyncResult asyncResult, Exception& exception)
   --- End of inner exception stack trace ---
   at System.Net.ServicePoint.GetConnection(PooledStream PooledStream, Object owner, Boolean async, IPAddress& address, Socket& abortSocket, Socket& abortSocket6)
   at System.Net.PooledStream.Activate(Object owningObject, Boolean async, GeneralAsyncDelegate asyncCallback)
   at System.Net.PooledStream.Activate(Object owningObject, GeneralAsyncDelegate asyncCallback)
   at System.Net.ConnectionPool.GetConnection(Object owningObject, GeneralAsyncDelegate asyncCallback, Int32 creationTimeout)
   at System.Net.Mail.SmtpConnection.GetConnection(ServicePoint servicePoint)
   at System.Net.Mail.SmtpTransport.GetConnection(ServicePoint servicePoint)
   at System.Net.Mail.SmtpClient.GetConnection()
   at System.Net.Mail.SmtpClient.Send(MailMessage message)
   --- End of inner exception stack trace ---
   at System.Net.Mail.SmtpClient.Send(MailMessage message)
   at Employee_Management_Services.Controllers.AdminController.SendEmailToEmployee(Employee employee) in D:\Employee_Management_Services\Employee_Management_Services\Controllers\AdminController.cs:line 176
   at Employee_Management_Services.Controllers.AdminController.Create(Employee employee, String username) in D:\Employee_Management_Services\Employee_Management_Services\Controllers\AdminController.cs:line 241
2018-05-08 18:23:25,131 [10] FATAL Employee_Management_Services.Controllers.AdminController - Employee not added.System.InvalidOperationException: Start may not be called on a promise-style task.
   at System.Threading.Tasks.Task.Start(TaskScheduler scheduler)
   at System.Threading.Tasks.Task.Start()
   at Employee_Management_Services.Controllers.AdminController.Create(Employee employee, String username) in D:\Employee_Management_Services\Employee_Management_Services\Controllers\AdminController.cs:line 288
2018-05-08 18:34:45,630 [5] FATAL Employee_Management_Services.Controllers.AdminController - Employee not added.System.InvalidOperationException: Start may not be called on a promise-style task.
   at System.Threading.Tasks.Task.Start(TaskScheduler scheduler)
   at System.Threading.Tasks.Task.Start()
   at Employee_Management_Services.Controllers.AdminController.Create(Employee employee, String username) in D:\Employee_Management_Services\Employee_Management_Services\Controllers\AdminController.cs:line 292
2018-05-08 18:37:54,247 [8] FATAL Employee_Management_Services.Controllers.AdminController - Employee not added.System.InvalidOperationException: Start may not be called on a promise-style task.
   at System.Threading.Tasks.Task.Start(TaskScheduler scheduler)
   at System.Threading.Tasks.Task.Start()
   at Employee_Management_Services.Controllers.AdminController.Create(Employee employee, String username)
2018-05-08 18:41:32,125 [5] FATAL Employee_Management_Services.Controllers.AdminController - Employee not added.System.InvalidOperationException: Start may not be called on a promise-style task.
   at System.Threading.Tasks.Task.Start(TaskScheduler scheduler)
   at System.Threading.Tasks.Task.Start()
   at Employee_Management_Services.Controllers.AdminController.Create(Employee employee, String username) in D:\Employee_Management_Services\Employee_Management_Services\Controllers\AdminController.cs:line 287
2018-05-08 19:11:23,471 [24] FATAL Employee_Management_Services.Controllers.AdminController - Employee not added.System.AggregateException: One or more errors occurred. ---> System.Threading.Tasks.TaskCanceledException: A task was canceled.
   --- End of inner exception stack trace ---
   at System.Threading.Tasks.Task.ThrowIfExceptional(Boolean includeTaskCanceledExceptions)
   at System.Threading.Tasks.Task`1.GetResultCore(Boolean waitCompletionNotification)
   at System.Threading.Tasks.Task`1.get_Result()
   at Employee_Management_Services.Controllers.AdminController.Create(Employee employee, String username) in D:\Employee_Management_Services\Employee_Management_Services\Controllers\AdminController.cs:line 253
---> (Inner Exception #0) System.Threading.Tasks.TaskCanceledException: A task was canceled.<---

2018-05-08 19:14:51,238 [17] FATAL Employee_Management_Services.Controllers.AdminController - Employee not added.System.AggregateException: One or more errors occurred. ---> System.Net.Http.HttpRequestException: An error occurred while sending the request. ---> System.Net.WebException: The underlying connection was closed: An unexpected error occurred on a receive. ---> System.IO.IOException: Unable to read data from the transport connection: An existing connection was forcibly closed by the remote host. ---> System.Net.Sockets.SocketException: An existing connection was forcibly closed by the remote host
   at System.Net.Sockets.Socket.EndReceive(IAsyncResult asyncResult)
   at System.Net.Sockets.NetworkStream.EndRead(IAsyncResult asyncResult)
   --- End of inner exception stack trace ---
   at System.Net.Sockets.NetworkStream.EndRead(IAsyncResult asyncResult)
   at System.Net.PooledStream.EndRead(IAsyncResult asyncResult)
   at System.Net.Connection.ReadCallback(IAsyncResult asyncResult)
   --- End of inner exception stack trace ---
   at System.Net.HttpWebRequest.EndGetResponse(IAsyncResult asyncResult)
   at System.Net.Http.HttpClientHandler.GetResponseCallback(IAsyncResult ar)
   --- End of inner exception stack trace ---
   --- End of inner exception stack trace ---
   at System.Threading.Tasks.Task.ThrowIfExceptional(Boolean includeTaskCanceledExceptions)
   at System.Threading.Tasks.Task`1.GetResultCore(Boolean waitCompletionNotification)
   at System.Threading.Tasks.Task`1.get_Result()
   at Employee_Management_Services.Controllers.AdminController.Create(Employee employee, String username) in D:\Employee_Management_Services\Employee_Management_Services\Controllers\AdminController.cs:line 253
---> (Inner Exception #0) System.Net.Http.HttpRequestException: An error occurred while sending the request. ---> System.Net.WebException: The underlying connection was closed: An unexpected error occurred on a receive. ---> System.IO.IOException: Unable to read data from the transport connection: An existing connection was forcibly closed by the remote host. ---> System.Net.Sockets.SocketException: An existing connection was forcibly closed by the remote host
   at System.Net.Sockets.Socket.EndReceive(IAsyncResult asyncResult)
   at System.Net.Sockets.NetworkStream.EndRead(IAsyncResult asyncResult)
   --- End of inner exception stack trace ---
   at System.Net.Sockets.NetworkStream.EndRead(IAsyncResult asyncResult)
   at System.Net.PooledStream.EndRead(IAsyncResult asyncResult)
   at System.Net.Connection.ReadCallback(IAsyncResult asyncResult)
   --- End of inner exception stack trace ---
   at System.Net.HttpWebRequest.EndGetResponse(IAsyncResult asyncResult)
   at System.Net.Http.HttpClientHandler.GetResponseCallback(IAsyncResult ar)
   --- End of inner exception stack trace ---<---

2018-05-08 20:47:41,941 [28] FATAL Employee_Management_Services.Controllers.AdminController - Employee not added.System.AggregateException: One or more errors occurred. ---> System.Threading.Tasks.TaskCanceledException: A task was canceled.
   --- End of inner exception stack trace ---
   at System.Threading.Tasks.Task.ThrowIfExceptional(Boolean includeTaskCanceledExceptions)
   at System.Threading.Tasks.Task`1.GetResultCore(Boolean waitCompletionNotification)
   at System.Threading.Tasks.Task`1.get_Result()
   at Employee_Management_Services.Controllers.AdminController.Create(Employee employee, String username) in D:\Employee_Management_Services\Employee_Management_Services\Controllers\AdminController.cs:line 253
---> (Inner Exception #0) System.Threading.Tasks.TaskCanceledException: A task was canceled.<---

2018-05-08 20:52:15,115 [36] FATAL Employee_Management_Services.Controllers.AdminController - Employee not added.System.AggregateException: One or more errors occurred. ---> System.Net.Http.HttpRequestException: An error occurred while sending the request. ---> System.Net.WebException: The underlying connection was closed: An unexpected error occurred on a receive. ---> System.IO.IOException: Unable to read data from the transport connection: An existing connection was forcibly closed by the remote host. ---> System.Net.Sockets.SocketException: An existing connection was forcibly closed by the remote host
   at System.Net.Sockets.Socket.EndReceive(IAsyncResult asyncResult)
   at System.Net.Sockets.NetworkStream.EndRead(IAsyncResult asyncResult)
   --- End of inner exception stack trace ---
   at System.Net.Sockets.NetworkStream.EndRead(IAsyncResult asyncResult)
   at System.Net.PooledStream.EndRead(IAsyncResult asyncResult)
   at System.Net.Connection.ReadCallback(IAsyncResult asyncResult)
   --- End of inner exception stack trace ---
   at System.Net.HttpWebRequest.EndGetResponse(IAsyncResult asyncResult)
   at System.Net.Http.HttpClientHandler.GetResponseCallback(IAsyncResult ar)
   --- End of inner exception stack trace ---
   --- End of inner exception stack trace ---
   at System.Threading.Tasks.Task.ThrowIfExceptional(Boolean includeTaskCanceledExceptions)
   at System.Threading.Tasks.Task`1.GetResultCore(Boolean waitCompletionNotification)
   at System.Threading.Tasks.Task`1.get_Result()
   at Employee_Management_Services.Controllers.AdminController.Create(Employee employee, String username) in D:\Employee_Management_Services\Employee_Management_Services\Controllers\AdminController.cs:line 253
---> (Inner Exception #0) System.Net.Http.HttpRequestException: An error occurred while sending the request. ---> System.Net.WebException: The underlying connection was closed: An unexpected error occurred on a receive. ---> System.IO.IOException: Unable to read data from the transport connection: An existing connection was forcibly closed by the remote host. ---> System.Net.Sockets.SocketException: An existing connection was forcibly closed by the remote host
   at System.Net.Sockets.Socket.EndReceive(IAsyncResult asyncResult)
   at System.Net.Sockets.NetworkStream.EndRead(IAsyncResult asyncResult)
   --- End of inner exception stack trace ---
   at System.Net.Sockets.NetworkStream.EndRead(IAsyncResult asyncResult)
   at System.Net.PooledStream.EndRead(IAsyncResult asyncResult)
   at System.Net.Connection.ReadCallback(IAsyncResult asyncResult)
   --- End of inner exception stack trace ---
   at System.Net.HttpWebRequest.EndGetResponse(IAsyncResult asyncResult)
   at System.Net.Http.HttpClientHandler.GetResponseCallback(IAsyncResult ar)
   --- End of inner exception stack trace ---<---

2018-05-08 20:57:54,045 [25] FATAL Employee_Management_Services.Controllers.AdminController - Employee not added.System.AggregateException: One or more errors occurred. ---> System.Net.Http.HttpRequestException: An error occurred while sending the request. ---> System.Net.WebException: The underlying connection was closed: An unexpected error occurred on a receive. ---> System.IO.IOException: Unable to read data from the transport connection: An existing connection was forcibly closed by the remote host. ---> System.Net.Sockets.SocketException: An existing connection was forcibly closed by the remote host
   at System.Net.Sockets.Socket.EndReceive(IAsyncResult asyncResult)
   at System.Net.Sockets.NetworkStream.EndRead(IAsyncResult asyncResult)
   --- End of inner exception stack trace ---
   at System.Net.Sockets.NetworkStream.EndRead(IAsyncResult asyncResult)
   at System.Net.PooledStream.EndRead(IAsyncResult asyncResult)
   at System.Net.Connection.ReadCallback(IAsyncResult asyncResult)
   --- End of inner exception stack trace ---
   at System.Net.HttpWebRequest.EndGetResponse(IAsyncResult asyncResult)
   at System.Net.Http.HttpClientHandler.GetResponseCallback(IAsyncResult ar)
   --- End of inner exception stack trace ---
   --- End of inner exception stack trace ---
   at System.Threading.Tasks.Task.ThrowIfExceptional(Boolean includeTaskCanceledExceptions)
   at System.Threading.Tasks.Task`1.GetResultCore(Boolean waitCompletionNotification)
   at System.Threading.Tasks.Task`1.get_Result()
   at Employee_Management_Services.Controllers.AdminController.Create(Employee employee, String username) in D:\Employee_Management_Services\Employee_Management_Services\Controllers\AdminController.cs:line 253
---> (Inner Exception #0) System.Net.Http.HttpRequestException: An error occurred while sending the request. ---> System.Net.WebException: The underlying connection was closed: An unexpected error occurred on a receive. ---> System.IO.IOException: Unable to read data from the transport connection: An existing connection was forcibly closed by the remote host. ---> System.Net.Sockets.SocketException: An existing connection was forcibly closed by the remote host
   at System.Net.Sockets.Socket.EndReceive(IAsyncResult asyncResult)
   at System.Net.Sockets.NetworkStream.EndRead(IAsyncResult asyncResult)
   --- End of inner exception stack trace ---
   at System.Net.Sockets.NetworkStream.EndRead(IAsyncResult asyncResult)
   at System.Net.PooledStream.EndRead(IAsyncResult asyncResult)
   at System.Net.Connection.ReadCallback(IAsyncResult asyncResult)
   --- End of inner exception stack trace ---
   at System.Net.HttpWebRequest.EndGetResponse(IAsyncResult asyncResult)
   at System.Net.Http.HttpClientHandler.GetResponseCallback(IAsyncResult ar)
   --- End of inner exception stack trace ---<---

2018-05-09 13:29:31,882 [55] FATAL Employee_Management_Services.Controllers.EmployeeController - System.NullReferenceException: Object reference not set to an instance of an object.
   at Employee_Management_Services.Controllers.EmployeeController.Index(String id, String organisationID, String sortOrder, String currentFilter, String searchString, Nullable`1 page, String departmentFilter, String genderFilter) in D:\Employee_Management_Services\Employee_Management_Services\Controllers\EmployeeController.cs:line 149
2018-05-09 13:29:36,773 [8] FATAL Employee_Management_Services.Controllers.EmployeeController - System.NullReferenceException: Object reference not set to an instance of an object.
   at Employee_Management_Services.Controllers.EmployeeController.Index(String id, String organisationID, String sortOrder, String currentFilter, String searchString, Nullable`1 page, String departmentFilter, String genderFilter) in D:\Employee_Management_Services\Employee_Management_Services\Controllers\EmployeeController.cs:line 149
2018-05-09 13:30:14,920 [6] FATAL Employee_Management_Services.Controllers.EmployeeController - System.NullReferenceException: Object reference not set to an instance of an object.
   at Employee_Management_Services.Controllers.EmployeeController.Index(String id, String organisationID, String sortOrder, String currentFilter, String searchString, Nullable`1 page, String departmentFilter, String genderFilter) in D:\Employee_Management_Services\Employee_Management_Services\Controllers\EmployeeController.cs:line 149
2018-05-09 14:30:51,497 [22] FATAL Employee_Management_Services.Controllers.EmployeeController - System.NullReferenceException: Object reference not set to an instance of an object.
   at Employee_Management_Services.Controllers.EmployeeController.Index(String id, String organisationID, String sortOrder, String currentFilter, String searchString, Nullable`1 page, String departmentFilter, String genderFilter) in D:\Employee_Management_Services\Employee_Management_Services\Controllers\EmployeeController.cs:line 149
2018-05-09 14:30:57,843 [22] FATAL Employee_Management_Services.Controllers.EmployeeController - System.NullReferenceException: Object reference not set to an instance of an object.
   at Employee_Management_Services.Controllers.EmployeeController.Index(String id, String organisationID, String sortOrder, String currentFilter, String searchString, Nullable`1 page, String departmentFilter, String genderFilter) in D:\Employee_Management_Services\Employee_Management_Services\Controllers\EmployeeController.cs:line 149
2018-05-09 16:02:09,584 [55] FATAL Employee_Management_Services.Controllers.EmployeeController - System.NullReferenceException: Object reference not set to an instance of an object.
   at Employee_Management_Services.Controllers.EmployeeController.ChangePassword(Int32 id, String organisationID, String user) in D:\Employee_Management_Services\Employee_Management_Services\Controllers\EmployeeController.cs:line 286
2018-05-10 09:43:23,770 [43] FATAL Employee_Management_Services.Controllers.EmployeeController - System.NullReferenceException: Object reference not set to an instance of an object.
   at Employee_Management_Services.Controllers.EmployeeController.Index(String id, String organisationID, String sortOrder, String currentFilter, String searchString, Nullable`1 page, String departmentFilter, String genderFilter) in D:\Employee_Management_Services\Employee_Management_Services\Controllers\EmployeeController.cs:line 149
2018-05-10 10:55:42,906 [7] FATAL Employee_Management_Services.Controllers.AdminController - Employee not added.System.InvalidOperationException: An asynchronous operation cannot be started at this time. Asynchronous operations may only be started within an asynchronous handler or module or during certain events in the Page lifecycle. If this exception occurred while executing a Page, ensure that the Page is marked <%@ Page Async="true" %>. This exception may also indicate an attempt to call an "async void" method, which is generally unsupported within ASP.NET request processing. Instead, the asynchronous method should return a Task, and the caller should await it.
   at System.Web.AspNetSynchronizationContext.OperationStarted()
   at System.Runtime.CompilerServices.AsyncVoidMethodBuilder.Create()
   at Employee_Management_Services.Controllers.AdminController.SendEmailToEmployee(Employee employee)
   at Employee_Management_Services.Controllers.AdminController.Create(Employee employee, String username) in D:\Employee_Management_Services\Employee_Management_Services\Controllers\AdminController.cs:line 261
2018-05-11 13:11:14,461 [10] FATAL Employee_Management_Services.Controllers.AdminController - System.AggregateException: One or more errors occurred. ---> System.Net.Http.HttpRequestException: An error occurred while sending the request. ---> System.Net.WebException: Unable to connect to the remote server ---> System.Net.Sockets.SocketException: No connection could be made because the target machine actively refused it 127.0.0.1:58410
   at System.Net.Sockets.Socket.EndConnect(IAsyncResult asyncResult)
   at System.Net.ServicePoint.ConnectSocketInternal(Boolean connectFailure, Socket s4, Socket s6, Socket& socket, IPAddress& address, ConnectSocketState state, IAsyncResult asyncResult, Exception& exception)
   --- End of inner exception stack trace ---
   at System.Net.HttpWebRequest.EndGetResponse(IAsyncResult asyncResult)
   at System.Net.Http.HttpClientHandler.GetResponseCallback(IAsyncResult ar)
   --- End of inner exception stack trace ---
   --- End of inner exception stack trace ---
   at System.Threading.Tasks.Task.ThrowIfExceptional(Boolean includeTaskCanceledExceptions)
   at System.Threading.Tasks.Task.Wait(Int32 millisecondsTimeout, CancellationToken cancellationToken)
   at System.Threading.Tasks.Task.Wait()
   at Employee_Management_Services.Controllers.AdminController.Edit(Int32 id, String userName, String organisationID) in D:\Employee_Management_Services\Employee_Management_Services\Controllers\AdminController.cs:line 319
---> (Inner Exception #0) System.Net.Http.HttpRequestException: An error occurred while sending the request. ---> System.Net.WebException: Unable to connect to the remote server ---> System.Net.Sockets.SocketException: No connection could be made because the target machine actively refused it 127.0.0.1:58410
   at System.Net.Sockets.Socket.EndConnect(IAsyncResult asyncResult)
   at System.Net.ServicePoint.ConnectSocketInternal(Boolean connectFailure, Socket s4, Socket s6, Socket& socket, IPAddress& address, ConnectSocketState state, IAsyncResult asyncResult, Exception& exception)
   --- End of inner exception stack trace ---
   at System.Net.HttpWebRequest.EndGetResponse(IAsyncResult asyncResult)
   at System.Net.Http.HttpClientHandler.GetResponseCallback(IAsyncResult ar)
   --- End of inner exception stack trace ---<---

2018-05-11 15:37:59,257 [23] FATAL Employee_Management_Services.Controllers.AdminController - System.AggregateException: One or more errors occurred. ---> System.Net.Http.HttpRequestException: An error occurred while sending the request. ---> System.Net.WebException: The underlying connection was closed: An unexpected error occurred on a receive. ---> System.IO.IOException: Unable to read data from the transport connection: An existing connection was forcibly closed by the remote host. ---> System.Net.Sockets.SocketException: An existing connection was forcibly closed by the remote host
   at System.Net.Sockets.Socket.EndReceive(IAsyncResult asyncResult)
   at System.Net.Sockets.NetworkStream.EndRead(IAsyncResult asyncResult)
   --- End of inner exception stack trace ---
   at System.Net.Sockets.NetworkStream.EndRead(IAsyncResult asyncResult)
   at System.Net.PooledStream.EndRead(IAsyncResult asyncResult)
   at System.Net.Connection.ReadCallback(IAsyncResult asyncResult)
   --- End of inner exception stack trace ---
   at System.Net.HttpWebRequest.EndGetResponse(IAsyncResult asyncResult)
   at System.Net.Http.HttpClientHandler.GetResponseCallback(IAsyncResult ar)
   --- End of inner exception stack trace ---
   --- End of inner exception stack trace ---
   at System.Threading.Tasks.Task.ThrowIfExceptional(Boolean includeTaskCanceledExceptions)
   at System.Threading.Tasks.Task`1.GetResultCore(Boolean waitCompletionNotification)
   at System.Threading.Tasks.Task`1.get_Result()
   at Employee_Management_Services.Controllers.AdminController.DeleteOrganisation(String id) in D:\Employee_Management_Services\Employee_Management_Services\Controllers\AdminController.cs:line 891
---> (Inner Exception #0) System.Net.Http.HttpRequestException: An error occurred while sending the request. ---> System.Net.WebException: The underlying connection was closed: An unexpected error occurred on a receive. ---> System.IO.IOException: Unable to read data from the transport connection: An existing connection was forcibly closed by the remote host. ---> System.Net.Sockets.SocketException: An existing connection was forcibly closed by the remote host
   at System.Net.Sockets.Socket.EndReceive(IAsyncResult asyncResult)
   at System.Net.Sockets.NetworkStream.EndRead(IAsyncResult asyncResult)
   --- End of inner exception stack trace ---
   at System.Net.Sockets.NetworkStream.EndRead(IAsyncResult asyncResult)
   at System.Net.PooledStream.EndRead(IAsyncResult asyncResult)
   at System.Net.Connection.ReadCallback(IAsyncResult asyncResult)
   --- End of inner exception stack trace ---
   at System.Net.HttpWebRequest.EndGetResponse(IAsyncResult asyncResult)
   at System.Net.Http.HttpClientHandler.GetResponseCallback(IAsyncResult ar)
   --- End of inner exception stack trace ---<---

2018-05-11 15:42:16,140 [9] FATAL Employee_Management_Services.Controllers.AdminController - System.AggregateException: One or more errors occurred. ---> System.Net.Http.HttpRequestException: An error occurred while sending the request. ---> System.Net.WebException: The underlying connection was closed: An unexpected error occurred on a receive. ---> System.IO.IOException: Unable to read data from the transport connection: An existing connection was forcibly closed by the remote host. ---> System.Net.Sockets.SocketException: An existing connection was forcibly closed by the remote host
   at System.Net.Sockets.Socket.EndReceive(IAsyncResult asyncResult)
   at System.Net.Sockets.NetworkStream.EndRead(IAsyncResult asyncResult)
   --- End of inner exception stack trace ---
   at System.Net.Sockets.NetworkStream.EndRead(IAsyncResult asyncResult)
   at System.Net.PooledStream.EndRead(IAsyncResult asyncResult)
   at System.Net.Connection.ReadCallback(IAsyncResult asyncResult)
   --- End of inner exception stack trace ---
   at System.Net.HttpWebRequest.EndGetResponse(IAsyncResult asyncResult)
   at System.Net.Http.HttpClientHandler.GetResponseCallback(IAsyncResult ar)
   --- End of inner exception stack trace ---
   --- End of inner exception stack trace ---
   at System.Threading.Tasks.Task.ThrowIfExceptional(Boolean includeTaskCanceledExceptions)
   at System.Threading.Tasks.Task`1.GetResultCore(Boolean waitCompletionNotification)
   at System.Threading.Tasks.Task`1.get_Result()
   at Employee_Management_Services.Controllers.AdminController.DeleteOrganisation(String id) in D:\Employee_Management_Services\Employee_Management_Services\Controllers\AdminController.cs:line 891
---> (Inner Exception #0) System.Net.Http.HttpRequestException: An error occurred while sending the request. ---> System.Net.WebException: The underlying connection was closed: An unexpected error occurred on a receive. ---> System.IO.IOException: Unable to read data from the transport connection: An existing connection was forcibly closed by the remote host. ---> System.Net.Sockets.SocketException: An existing connection was forcibly closed by the remote host
   at System.Net.Sockets.Socket.EndReceive(IAsyncResult asyncResult)
   at System.Net.Sockets.NetworkStream.EndRead(IAsyncResult asyncResult)
   --- End of inner exception stack trace ---
   at System.Net.Sockets.NetworkStream.EndRead(IAsyncResult asyncResult)
   at System.Net.PooledStream.EndRead(IAsyncResult asyncResult)
   at System.Net.Connection.ReadCallback(IAsyncResult asyncResult)
   --- End of inner exception stack trace ---
   at System.Net.HttpWebRequest.EndGetResponse(IAsyncResult asyncResult)
   at System.Net.Http.HttpClientHandler.GetResponseCallback(IAsyncResult ar)
   --- End of inner exception stack trace ---<---

2018-05-11 15:44:27,582 [5] FATAL Employee_Management_Services.Controllers.AdminController - System.NullReferenceException: Object reference not set to an instance of an object.
   at Employee_Management_Services.Controllers.AdminController.DeleteOrganisation(String id) in D:\Employee_Management_Services\Employee_Management_Services\Controllers\AdminController.cs:line 888
2018-05-11 15:45:33,399 [5] FATAL Employee_Management_Services.Controllers.AdminController - System.NullReferenceException: Object reference not set to an instance of an object.
   at Employee_Management_Services.Controllers.AdminController.DeleteOrganisation(String id) in D:\Employee_Management_Services\Employee_Management_Services\Controllers\AdminController.cs:line 888
2018-05-11 15:48:29,691 [5] FATAL Employee_Management_Services.Controllers.AdminController - System.NullReferenceException: Object reference not set to an instance of an object.
   at Employee_Management_Services.Controllers.AdminController.DeleteOrganisation(String id) in D:\Employee_Management_Services\Employee_Management_Services\Controllers\AdminController.cs:line 888
2018-05-11 16:02:04,756 [14] FATAL Employee_Management_Services.Controllers.AdminController - System.AggregateException: One or more errors occurred. ---> System.Net.Http.HttpRequestException: An error occurred while sending the request. ---> System.Net.WebException: The underlying connection was closed: An unexpected error occurred on a receive. ---> System.IO.IOException: Unable to read data from the transport connection: An existing connection was forcibly closed by the remote host. ---> System.Net.Sockets.SocketException: An existing connection was forcibly closed by the remote host
   at System.Net.Sockets.Socket.EndReceive(IAsyncResult asyncResult)
   at System.Net.Sockets.NetworkStream.EndRead(IAsyncResult asyncResult)
   --- End of inner exception stack trace ---
   at System.Net.Sockets.NetworkStream.EndRead(IAsyncResult asyncResult)
   at System.Net.PooledStream.EndRead(IAsyncResult asyncResult)
   at System.Net.Connection.ReadCallback(IAsyncResult asyncResult)
   --- End of inner exception stack trace ---
   at System.Net.HttpWebRequest.EndGetResponse(IAsyncResult asyncResult)
   at System.Net.Http.HttpClientHandler.GetResponseCallback(IAsyncResult ar)
   --- End of inner exception stack trace ---
   --- End of inner exception stack trace ---
   at System.Threading.Tasks.Task.ThrowIfExceptional(Boolean includeTaskCanceledExceptions)
   at System.Threading.Tasks.Task`1.GetResultCore(Boolean waitCompletionNotification)
   at System.Threading.Tasks.Task`1.get_Result()
   at Employee_Management_Services.Controllers.AdminController.DeleteOrganisation(Admin organisation) in D:\Employee_Management_Services\Employee_Management_Services\Controllers\AdminController.cs:line 891
---> (Inner Exception #0) System.Net.Http.HttpRequestException: An error occurred while sending the request. ---> System.Net.WebException: The underlying connection was closed: An unexpected error occurred on a receive. ---> System.IO.IOException: Unable to read data from the transport connection: An existing connection was forcibly closed by the remote host. ---> System.Net.Sockets.SocketException: An existing connection was forcibly closed by the remote host
   at System.Net.Sockets.Socket.EndReceive(IAsyncResult asyncResult)
   at System.Net.Sockets.NetworkStream.EndRead(IAsyncResult asyncResult)
   --- End of inner exception stack trace ---
   at System.Net.Sockets.NetworkStream.EndRead(IAsyncResult asyncResult)
   at System.Net.PooledStream.EndRead(IAsyncResult asyncResult)
   at System.Net.Connection.ReadCallback(IAsyncResult asyncResult)
   --- End of inner exception stack trace ---
   at System.Net.HttpWebRequest.EndGetResponse(IAsyncResult asyncResult)
   at System.Net.Http.HttpClientHandler.GetResponseCallback(IAsyncResult ar)
   --- End of inner exception stack trace ---<---

2018-05-11 16:10:44,965 [8] FATAL Employee_Management_Services.Controllers.AdminController - System.AggregateException: One or more errors occurred. ---> System.Threading.Tasks.TaskCanceledException: A task was canceled.
   --- End of inner exception stack trace ---
   at System.Threading.Tasks.Task.ThrowIfExceptional(Boolean includeTaskCanceledExceptions)
   at System.Threading.Tasks.Task`1.GetResultCore(Boolean waitCompletionNotification)
   at System.Threading.Tasks.Task`1.get_Result()
   at Employee_Management_Services.Controllers.AdminController.DeleteOrganisation(String organisation) in D:\Employee_Management_Services\Employee_Management_Services\Controllers\AdminController.cs:line 891
---> (Inner Exception #0) System.Threading.Tasks.TaskCanceledException: A task was canceled.<---

2018-05-12 15:10:02,599 [8] FATAL Employee_Management_Services.Controllers.AdminController - System.AggregateException: One or more errors occurred. ---> System.Threading.Tasks.TaskCanceledException: A task was canceled.
   --- End of inner exception stack trace ---
   at System.Threading.Tasks.Task.ThrowIfExceptional(Boolean includeTaskCanceledExceptions)
   at System.Threading.Tasks.Task`1.GetResultCore(Boolean waitCompletionNotification)
   at System.Threading.Tasks.Task`1.get_Result()
   at Employee_Management_Services.Controllers.AdminController.DeleteOrganisation(String organisation) in D:\Employee_Management_Services\Employee_Management_Services\Controllers\AdminController.cs:line 891
---> (Inner Exception #0) System.Threading.Tasks.TaskCanceledException: A task was canceled.<---

2018-05-12 15:14:52,110 [22] FATAL Employee_Management_Services.Controllers.AdminController - System.AggregateException: One or more errors occurred. ---> System.Threading.Tasks.TaskCanceledException: A task was canceled.
   --- End of inner exception stack trace ---
   at System.Threading.Tasks.Task.ThrowIfExceptional(Boolean includeTaskCanceledExceptions)
   at System.Threading.Tasks.Task`1.GetResultCore(Boolean waitCompletionNotification)
   at System.Threading.Tasks.Task`1.get_Result()
   at Employee_Management_Services.Controllers.AdminController.DeleteOrganisation(String organisation) in D:\Employee_Management_Services\Employee_Management_Services\Controllers\AdminController.cs:line 891
---> (Inner Exception #0) System.Threading.Tasks.TaskCanceledException: A task was canceled.<---

2018-05-12 15:37:41,225 [37] FATAL Employee_Management_Services.Controllers.AdminController - Employee not added.System.AggregateException: One or more errors occurred. ---> System.Net.Http.HttpRequestException: An error occurred while sending the request. ---> System.Net.WebException: The underlying connection was closed: An unexpected error occurred on a receive. ---> System.IO.IOException: Unable to read data from the transport connection: An existing connection was forcibly closed by the remote host. ---> System.Net.Sockets.SocketException: An existing connection was forcibly closed by the remote host
   at System.Net.Sockets.Socket.EndReceive(IAsyncResult asyncResult)
   at System.Net.Sockets.NetworkStream.EndRead(IAsyncResult asyncResult)
   --- End of inner exception stack trace ---
   at System.Net.Sockets.NetworkStream.EndRead(IAsyncResult asyncResult)
   at System.Net.PooledStream.EndRead(IAsyncResult asyncResult)
   at System.Net.Connection.ReadCallback(IAsyncResult asyncResult)
   --- End of inner exception stack trace ---
   at System.Net.HttpWebRequest.EndGetResponse(IAsyncResult asyncResult)
   at System.Net.Http.HttpClientHandler.GetResponseCallback(IAsyncResult ar)
   --- End of inner exception stack trace ---
   --- End of inner exception stack trace ---
   at System.Threading.Tasks.Task.ThrowIfExceptional(Boolean includeTaskCanceledExceptions)
   at System.Threading.Tasks.Task`1.GetResultCore(Boolean waitCompletionNotification)
   at System.Threading.Tasks.Task`1.get_Result()
   at Employee_Management_Services.Controllers.AdminController.Create(Employee employee, String username) in D:\Employee_Management_Services\Employee_Management_Services\Controllers\AdminController.cs:line 263
---> (Inner Exception #0) System.Net.Http.HttpRequestException: An error occurred while sending the request. ---> System.Net.WebException: The underlying connection was closed: An unexpected error occurred on a receive. ---> System.IO.IOException: Unable to read data from the transport connection: An existing connection was forcibly closed by the remote host. ---> System.Net.Sockets.SocketException: An existing connection was forcibly closed by the remote host
   at System.Net.Sockets.Socket.EndReceive(IAsyncResult asyncResult)
   at System.Net.Sockets.NetworkStream.EndRead(IAsyncResult asyncResult)
   --- End of inner exception stack trace ---
   at System.Net.Sockets.NetworkStream.EndRead(IAsyncResult asyncResult)
   at System.Net.PooledStream.EndRead(IAsyncResult asyncResult)
   at System.Net.Connection.ReadCallback(IAsyncResult asyncResult)
   --- End of inner exception stack trace ---
   at System.Net.HttpWebRequest.EndGetResponse(IAsyncResult asyncResult)
   at System.Net.Http.HttpClientHandler.GetResponseCallback(IAsyncResult ar)
   --- End of inner exception stack trace ---<---

2018-05-12 15:39:39,080 [37] FATAL Employee_Management_Services.Controllers.AdminController - System.AggregateException: One or more errors occurred. ---> System.Net.Http.HttpRequestException: An error occurred while sending the request. ---> System.Net.WebException: Unable to connect to the remote server ---> System.Net.Sockets.SocketException: No connection could be made because the target machine actively refused it 127.0.0.1:58410
   at System.Net.Sockets.Socket.EndConnect(IAsyncResult asyncResult)
   at System.Net.ServicePoint.ConnectSocketInternal(Boolean connectFailure, Socket s4, Socket s6, Socket& socket, IPAddress& address, ConnectSocketState state, IAsyncResult asyncResult, Exception& exception)
   --- End of inner exception stack trace ---
   at System.Net.HttpWebRequest.EndGetRequestStream(IAsyncResult asyncResult, TransportContext& context)
   at System.Net.Http.HttpClientHandler.GetRequestStreamCallback(IAsyncResult ar)
   --- End of inner exception stack trace ---
   --- End of inner exception stack trace ---
   at System.Threading.Tasks.Task.ThrowIfExceptional(Boolean includeTaskCanceledExceptions)
   at System.Threading.Tasks.Task`1.GetResultCore(Boolean waitCompletionNotification)
   at System.Threading.Tasks.Task`1.get_Result()
   at Employee_Management_Services.Controllers.AdminController.Login(Admin admin) in D:\Employee_Management_Services\Employee_Management_Services\Controllers\AdminController.cs:line 503
---> (Inner Exception #0) System.Net.Http.HttpRequestException: An error occurred while sending the request. ---> System.Net.WebException: Unable to connect to the remote server ---> System.Net.Sockets.SocketException: No connection could be made because the target machine actively refused it 127.0.0.1:58410
   at System.Net.Sockets.Socket.EndConnect(IAsyncResult asyncResult)
   at System.Net.ServicePoint.ConnectSocketInternal(Boolean connectFailure, Socket s4, Socket s6, Socket& socket, IPAddress& address, ConnectSocketState state, IAsyncResult asyncResult, Exception& exception)
   --- End of inner exception stack trace ---
   at System.Net.HttpWebRequest.EndGetRequestStream(IAsyncResult asyncResult, TransportContext& context)
   at System.Net.Http.HttpClientHandler.GetRequestStreamCallback(IAsyncResult ar)
   --- End of inner exception stack trace ---<---

2018-05-12 15:39:51,899 [5] FATAL Employee_Management_Services.Controllers.AdminController - System.AggregateException: One or more errors occurred. ---> System.Net.Http.HttpRequestException: An error occurred while sending the request. ---> System.Net.WebException: Unable to connect to the remote server ---> System.Net.Sockets.SocketException: No connection could be made because the target machine actively refused it 127.0.0.1:58410
   at System.Net.Sockets.Socket.EndConnect(IAsyncResult asyncResult)
   at System.Net.ServicePoint.ConnectSocketInternal(Boolean connectFailure, Socket s4, Socket s6, Socket& socket, IPAddress& address, ConnectSocketState state, IAsyncResult asyncResult, Exception& exception)
   --- End of inner exception stack trace ---
   at System.Net.HttpWebRequest.EndGetRequestStream(IAsyncResult asyncResult, TransportContext& context)
   at System.Net.Http.HttpClientHandler.GetRequestStreamCallback(IAsyncResult ar)
   --- End of inner exception stack trace ---
   --- End of inner exception stack trace ---
   at System.Threading.Tasks.Task.ThrowIfExceptional(Boolean includeTaskCanceledExceptions)
   at System.Threading.Tasks.Task`1.GetResultCore(Boolean waitCompletionNotification)
   at System.Threading.Tasks.Task`1.get_Result()
   at Employee_Management_Services.Controllers.AdminController.Login(Admin admin) in D:\Employee_Management_Services\Employee_Management_Services\Controllers\AdminController.cs:line 503
---> (Inner Exception #0) System.Net.Http.HttpRequestException: An error occurred while sending the request. ---> System.Net.WebException: Unable to connect to the remote server ---> System.Net.Sockets.SocketException: No connection could be made because the target machine actively refused it 127.0.0.1:58410
   at System.Net.Sockets.Socket.EndConnect(IAsyncResult asyncResult)
   at System.Net.ServicePoint.ConnectSocketInternal(Boolean connectFailure, Socket s4, Socket s6, Socket& socket, IPAddress& address, ConnectSocketState state, IAsyncResult asyncResult, Exception& exception)
   --- End of inner exception stack trace ---
   at System.Net.HttpWebRequest.EndGetRequestStream(IAsyncResult asyncResult, TransportContext& context)
   at System.Net.Http.HttpClientHandler.GetRequestStreamCallback(IAsyncResult ar)
   --- End of inner exception stack trace ---<---

2018-05-12 21:22:36,664 [10] FATAL Employee_Management_Services.Controllers.HomeController - Login FailedSystem.AggregateException: One or more errors occurred. ---> System.Net.Http.HttpRequestException: An error occurred while sending the request. ---> System.Net.WebException: The underlying connection was closed: An unexpected error occurred on a receive. ---> System.IO.IOException: Unable to read data from the transport connection: An existing connection was forcibly closed by the remote host. ---> System.Net.Sockets.SocketException: An existing connection was forcibly closed by the remote host
   at System.Net.Sockets.Socket.EndReceive(IAsyncResult asyncResult)
   at System.Net.Sockets.NetworkStream.EndRead(IAsyncResult asyncResult)
   --- End of inner exception stack trace ---
   at System.Net.Sockets.NetworkStream.EndRead(IAsyncResult asyncResult)
   at System.Net.PooledStream.EndRead(IAsyncResult asyncResult)
   at System.Net.Connection.ReadCallback(IAsyncResult asyncResult)
   --- End of inner exception stack trace ---
   at System.Net.HttpWebRequest.EndGetResponse(IAsyncResult asyncResult)
   at System.Net.Http.HttpClientHandler.GetResponseCallback(IAsyncResult ar)
   --- End of inner exception stack trace ---
   --- End of inner exception stack trace ---
   at System.Threading.Tasks.Task.ThrowIfExceptional(Boolean includeTaskCanceledExceptions)
   at System.Threading.Tasks.Task`1.GetResultCore(Boolean waitCompletionNotification)
   at System.Threading.Tasks.Task`1.get_Result()
   at Employee_Management_Services.Controllers.HomeController.Login(Employee employee) in D:\Employee_Management_Services\Employee_Management_Services\Controllers\HomeController.cs:line 102
---> (Inner Exception #0) System.Net.Http.HttpRequestException: An error occurred while sending the request. ---> System.Net.WebException: The underlying connection was closed: An unexpected error occurred on a receive. ---> System.IO.IOException: Unable to read data from the transport connection: An existing connection was forcibly closed by the remote host. ---> System.Net.Sockets.SocketException: An existing connection was forcibly closed by the remote host
   at System.Net.Sockets.Socket.EndReceive(IAsyncResult asyncResult)
   at System.Net.Sockets.NetworkStream.EndRead(IAsyncResult asyncResult)
   --- End of inner exception stack trace ---
   at System.Net.Sockets.NetworkStream.EndRead(IAsyncResult asyncResult)
   at System.Net.PooledStream.EndRead(IAsyncResult asyncResult)
   at System.Net.Connection.ReadCallback(IAsyncResult asyncResult)
   --- End of inner exception stack trace ---
   at System.Net.HttpWebRequest.EndGetResponse(IAsyncResult asyncResult)
   at System.Net.Http.HttpClientHandler.GetResponseCallback(IAsyncResult ar)
   --- End of inner exception stack trace ---<---

2019-01-23 12:23:57,067 [9] FATAL Employee_Management_Services.Controllers.AdminController - System.AggregateException: One or more errors occurred. ---> System.Threading.Tasks.TaskCanceledException: A task was canceled.
   --- End of inner exception stack trace ---
   at System.Threading.Tasks.Task.ThrowIfExceptional(Boolean includeTaskCanceledExceptions)
   at System.Threading.Tasks.Task`1.GetResultCore(Boolean waitCompletionNotification)
   at System.Threading.Tasks.Task`1.get_Result()
   at Employee_Management_Services.Controllers.AdminController.Login(Admin admin) in G:\LeadSquared\Employee_Management_Services\Employee_Management_Services\Controllers\AdminController.cs:line 443
---> (Inner Exception #0) System.Threading.Tasks.TaskCanceledException: A task was canceled.<---

2019-01-23 12:26:20,556 [9] FATAL Employee_Management_Services.Controllers.AdminController - System.AggregateException: One or more errors occurred. ---> System.Net.Http.HttpRequestException: An error occurred while sending the request. ---> System.Net.WebException: The underlying connection was closed: An unexpected error occurred on a receive. ---> System.IO.IOException: Unable to read data from the transport connection: An existing connection was forcibly closed by the remote host. ---> System.Net.Sockets.SocketException: An existing connection was forcibly closed by the remote host
   at System.Net.Sockets.Socket.EndReceive(IAsyncResult asyncResult)
   at System.Net.Sockets.NetworkStream.EndRead(IAsyncResult asyncResult)
   --- End of inner exception stack trace ---
   at System.Net.Sockets.NetworkStream.EndRead(IAsyncResult asyncResult)
   at System.Net.PooledStream.EndRead(IAsyncResult asyncResult)
   at System.Net.Connection.ReadCallback(IAsyncResult asyncResult)
   --- End of inner exception stack trace ---
   at System.Net.HttpWebRequest.EndGetResponse(IAsyncResult asyncResult)
   at System.Net.Http.HttpClientHandler.GetResponseCallback(IAsyncResult ar)
   --- End of inner exception stack trace ---
   --- End of inner exception stack trace ---
   at System.Threading.Tasks.Task.ThrowIfExceptional(Boolean includeTaskCanceledExceptions)
   at System.Threading.Tasks.Task`1.GetResultCore(Boolean waitCompletionNotification)
   at System.Threading.Tasks.Task`1.get_Result()
   at Employee_Management_Services.Controllers.AdminController.Login(Admin admin) in G:\LeadSquared\Employee_Management_Services\Employee_Management_Services\Controllers\AdminController.cs:line 443
---> (Inner Exception #0) System.Net.Http.HttpRequestException: An error occurred while sending the request. ---> System.Net.WebException: The underlying connection was closed: An unexpected error occurred on a receive. ---> System.IO.IOException: Unable to read data from the transport connection: An existing connection was forcibly closed by the remote host. ---> System.Net.Sockets.SocketException: An existing connection was forcibly closed by the remote host
   at System.Net.Sockets.Socket.EndReceive(IAsyncResult asyncResult)
   at System.Net.Sockets.NetworkStream.EndRead(IAsyncResult asyncResult)
   --- End of inner exception stack trace ---
   at System.Net.Sockets.NetworkStream.EndRead(IAsyncResult asyncResult)
   at System.Net.PooledStream.EndRead(IAsyncResult asyncResult)
   at System.Net.Connection.ReadCallback(IAsyncResult asyncResult)
   --- End of inner exception stack trace ---
   at System.Net.HttpWebRequest.EndGetResponse(IAsyncResult asyncResult)
   at System.Net.Http.HttpClientHandler.GetResponseCallback(IAsyncResult ar)
   --- End of inner exception stack trace ---<---

2019-01-23 12:32:06,549 [21] FATAL Employee_Management_Services.Controllers.AdminController - System.AggregateException: One or more errors occurred. ---> System.Threading.Tasks.TaskCanceledException: A task was canceled.
   --- End of inner exception stack trace ---
   at System.Threading.Tasks.Task.ThrowIfExceptional(Boolean includeTaskCanceledExceptions)
   at System.Threading.Tasks.Task`1.GetResultCore(Boolean waitCompletionNotification)
   at System.Threading.Tasks.Task`1.get_Result()
   at Employee_Management_Services.Controllers.AdminController.Login(Admin admin) in G:\LeadSquared\Employee_Management_Services\Employee_Management_Services\Controllers\AdminController.cs:line 443
---> (Inner Exception #0) System.Threading.Tasks.TaskCanceledException: A task was canceled.<---

2019-01-23 16:18:02,918 [18] FATAL Employee_Management_Services.Controllers.AdminController - System.AggregateException: One or more errors occurred. ---> System.Threading.Tasks.TaskCanceledException: A task was canceled.
   --- End of inner exception stack trace ---
   at System.Threading.Tasks.Task.ThrowIfExceptional(Boolean includeTaskCanceledExceptions)
   at System.Threading.Tasks.Task`1.GetResultCore(Boolean waitCompletionNotification)
   at System.Threading.Tasks.Task`1.get_Result()
   at Employee_Management_Services.Controllers.AdminController.DeleteOrganisation(String organisation) in G:\LeadSquared\Employee_Management_Services\Employee_Management_Services\Controllers\AdminController.cs:line 831
---> (Inner Exception #0) System.Threading.Tasks.TaskCanceledException: A task was canceled.<---

2019-10-20 02:23:04,610 [18] FATAL Employee_Management_Services.Controllers.AdminController - Employee not added.System.AggregateException: One or more errors occurred. ---> System.Threading.Tasks.TaskCanceledException: A task was canceled.
   --- End of inner exception stack trace ---
   at System.Threading.Tasks.Task.ThrowIfExceptional(Boolean includeTaskCanceledExceptions)
   at System.Threading.Tasks.Task`1.GetResultCore(Boolean waitCompletionNotification)
   at System.Threading.Tasks.Task`1.get_Result()
   at Employee_Management_Services.Controllers.AdminController.Create(Employee employee, String username) in G:\LeadSquared\Employee_Management_Services\Employee_Management_Services\Controllers\AdminController.cs:line 204
---> (Inner Exception #0) System.Threading.Tasks.TaskCanceledException: A task was canceled.<---

